Workbook
Name Fallas: [1]Configuracion!$Y$3:$Y$7
Name Horas_programadas: #REF!

Sheet Resultados

Sheet Instrucciones
B2: PRUEBA DE EXCEL
B6: Formatos - 10%
B7: Instrucciones: Aplicar las preguntas en la hoja correspondiente. | D7: Aplicar en Hoja | E7: Validacion
B8: 1 | C8: Retira la opción de mostrar Líneas de cuadricula en todas las hojas. | D8: Todas | E8: Se revisan todas las hojas
B9: 2 | C9: Cambia el nombre de la "Hoja2" por "Base" | D9: Hoja2 | E9: Se revisa la pestana
B10: 3 | C10: Aplica todos los bordes a la tabla. | D10: Base | E10: Se revisa la hoja Base
B11: 4 | C11: Aplicar formato de % con 2 decimales a la columna "J" | D11: Base | E11: Se revisa la hoja Base
B12: 5 | C12: Aplicar el formato de fecha personalizado "dd-mmm-aa" a la columna "A" | D12: Base | E12: Se revisa la hoja Base
B13: 6 | C13: Aplicar formato de hora personalizado "HH:MM:SS" a la columna "H" e "I" | D13: Base | E13: Se revisa la hoja Base
B14: 7 | C14: Quitar los espacios y caracteres de cada celda en la columna "D" de tal modo que queden puros números | D14: Base | E14: Que comando o formula uso? R: ulitice la opcion de remplazar con el comando de incono + L y la formula de limpiar por si tiene espacion que no se van con la opcion de remplazar
B15: 8 | C15: Ajusta el ancho de las columnas y centrar los datos de tal modo que se pueda leer claramente la tabla. | D15: Base | E15: Se revisa la hoja Base
B16: 9 | C16: Insertar un Filtro en los encabezados de la tabla | D16: Base | E16: Se revisa la hoja Base
B17: 10 | C17: Ordenar datos de forma ascendente por la columna "B" | D17: Base | E17: Se revisa la hoja Base
B18: 11 | C18: Aplicar formato condicional a la columna "J" con los siguientes criterios: Celda color rojo y Letras Amarillas si el resultado es mayor o igual a 90%, Celda color Verde oscuro y Letras Verde Claro si el resultado es menor a 90% | D18: Base | E18: Se revisa la hoja Base
B19: 12 | C19: Insertar un Comentario en la celda "C35" con su nombre completo. | D19: Instrucciones | E19: Se revisa la hoja Base
B21: Formulas y Validación - 30%
B22: Instrucciones | D22: Aplicar en Hoja | E22: Aplicar formula
B23: 1 | C23: Formula que nos arroje que día es hoy. Ejem: Martes, 23 de enero del 2011 | D23: ======> | E23: =TODAY() -> 45987 | G23: =HOY()
B24: 2 | C24: Formula que arroje la suma de la columna "H" únicamente para las horas programadas, esto de la hoja "Base" | D24: ======> | E24: =COUNTIF(base!H:H,"16:303:00") -> 0 | G24: =contar.si.cojunto
B25: 3 | C25: Formula que arroje únicamente la suma de la columna "H" de los datos visibles ( es decir si tengo datos filtrados únicamente arrojará la suma de los datos visibles) , esto de la hoja "Base" | D25: ======> | E25: =COUNTA(base!F2,base!F3,base!F13,base!F14,) -> 5 | G25: =CONTARA(base!F2;base!F3;base!F13;base!F14;)
B26: 4 | C26: Formula que arroje el nombre del agente perteneciente al numero de Avaya que se ingrese en la celda "E26" si este se encuentra en la hoja Base de lo contrario Arrojar el texto "No Encontrado". | D26: ======> | E26: =_xlfn.XLOOKUP(base!E26,base!E:E,base!C:C,"NO ENCONTRADO",0) -> Eder Garza | G26: =BUSCARX(base!E26;base!E:E;base!C:C;"NO ENCONTRADO";0)
B27: 5 | C27: Formula que junte las celdas "E23 y "F23" de la hoja base | D27: ======> | E27: =base!E23&base!F23 -> TLGWMVazquez, Jose | G27: =base!E23&base!F23
B28: 6 | C28: Formula que arroje el total de asistencias de la hoja Base ( las asistencias aparecen como "1" en la columna "G" | D28: ======> | E28: =COUNTIF(base!G:G,1) -> 60 | G28: =CONTAR.SI(base!G:G;1)
B29: 7 | C29: Formula que arroje el total de agentes en la hoja "Base" | D29: ======> | E29: =COUNTA(base!F:F) -> 143 | G29: =CONTARA(base!F:F)
B30: 8 | C30: Formula que arroje el texto de la celda "C40" en Mayúsculas | D30: ======> | E30: =UPPER(base!C40) -> ANGEL PUENTE | G30: =MAYUSC(base!C40)
B31: 9 | C31: Ingresar Validación de datos, que solamente permita ingresar números enteros del 1 al 5. | D31: ======> | E31: 5
B32: 10 | C32: Ingresar Validación que despliegue una lista del rango "B21:B29" de la hoja base | D32: ======>
B34: Grafica - 30%
B35: Instrucciones: Aplicar las preguntas en la hoja correspondiente. | D35: Aplicar en Hoja | E35: Validacion
B36: 1 | C36: Generar una Tabla en base a la hoja "Base" la cual muestre los resultados de Adherencia a nivel supervisor, tomar en cuenta que no es un promedio de los resultados de adherencia por lo cual necesitan recalcularlo en base a la siguiente formula: %ADH = Conexion en adherencia / horas programadas | D36: Tabla Dinámica | E36: Se realiza grafica en hoja Base
B37: 2 | C37: Generar una Gráfica de Barras en base a la tabla generada con la pregunta anterior. | D37: Gráfica | E37: Se realiza grafica en hoja Base
B39: Tabla Dinámica - 30%
B40: Instrucciones: Aplicar las preguntas en la hoja correspondiente. | D40: Aplicar en Hoja | E40: Validacion
B41: 1 | C41: Generar una Tabla Dinámica en base a la hoja "Base" la cual muestre los resultados de Adherencia a nivel Acm, Supervisor y Agente, tomar en cuenta que no es un promedio de los resultados de adherencia por lo cual necesitan insertar un campo calculado con la siguiente formula: %ADH = Conexion en adherencia/horas programadas | D41: Tabla Dinámica y grafica | E41: Se realiza grafica en hoja Base

Sheet base
A1: Date | B1: Acm | C1: Supervisor | D1: Avaya | E1: LOB | F1: Agent Name | G1: Asistencia | H1: Horas programadas | I1: Conexión en adherencia | J1: % In Adherence | K1: Resultado Adherencia | L1: CONTAR AGENTE NO DUPLICADO | N1: HORA PROGRAMADA BUSCADA 16:30:00
A2: 40622 | B2: Dulce Pedraza | C2: Eder Garza | D2: 77476 | E2: TLGM | F2: Martinez, Daniela | G2: 1 | H2: 2.6875 | I2: 2.6743056 | J2: 0.9627451 | K2: 0.99509044 | L2: =COUNTIF(F:F,F2) -> 1 | N2: =IF(H2<>"16:00:00",1,0) -> 1
A3: 40621 | B3: Dulce Pedraza | C3: Eder Garza | D3: 79476 | E3: TLGM | F3: Lozano, Roberto | G3: 1 | H3: 2.6458333 | I3: 2.6326389 | J3: 0.9627451 | K3: 0.99501312 | L3: =COUNTIF(F:F,F3) -> 1 | N3: =IF(H3<>"16:00:00",1,0) -> 1
A4: 40620 | B4: Dulce Pedraza | C4: Eder Garza | D4: 79634 | E4: TLGM | F4: Lopez, Andrea | G4: 1 | H4: 2.6041667 | I4: 2.5909722 | J4: 0.9627451 | K4: 0.99493333 | L4: =COUNTIF(F:F,F4) -> 1 | N4: =IF(H4<>"16:00:00",1,0) -> 1
A5: 40619 | B5: Dulce Pedraza | C5: Eder Garza | D5: 79390 | E5: TLGWM | F5: Rios, Alejandra | G5: 1 | H5: 2.5625 | I5: 2.5493056 | J5: 0.9627451 | K5: 0.99485095 | L5: =COUNTIF(F:F,F5) -> 1 | N5: =IF(H5<>"16:00:00",1,0) -> 1
A6: 40618 | B6: Dulce Pedraza | C6: Eder Garza | D6: 77834743 | E6: TLGWM | F6: Nuñez, Carolina | G6: 1 | H6: 2.5208333 | I6: 2.5076389 | J6: 0.9627451 | K6: 0.99476584 | L6: =COUNTIF(F:F,F6) -> 1 | N6: =IF(H6<>"16:00:00",1,0) -> 1
A7: 40617 | B7: Dulce Pedraza | C7: Eder Garza | D7: 77834565 | E7: TLGM | F7: Monsivais, Claudette | G7: 1 | H7: 2.4791667 | I7: 2.4659722 | J7: 0.9627451 | K7: 0.99467787 | L7: =COUNTIF(F:F,F7) -> 1 | N7: =IF(H7<>"16:00:00",1,0) -> 1
A8: 40616 | B8: Dulce Pedraza | C8: Eder Garza | D8: 75147 | E8: TLGWM | F8: Martinez, Roberto | G8: 1 | H8: 2.4375 | I8: 2.4243056 | J8: 0.9627451 | K8: 0.99458689 | L8: =COUNTIF(F:F,F8) -> 1 | N8: =IF(H8<>"16:00:00",1,0) -> 1
A9: 40615 | B9: Dulce Pedraza | C9: Eder Garza | D9: 77834046 | E9: TLGWM | F9: Gonzalez, Juan | G9: 1 | H9: 2.3958333 | I9: 2.3826389 | J9: 0.9627451 | K9: 0.99449275 | L9: =COUNTIF(F:F,F9) -> 1 | N9: =IF(H9<>"16:00:00",1,0) -> 1
A10: 40614 | B10: Dulce Pedraza | C10: Eder Garza | D10: 77077834 | E10: TLGM | F10: Gonzalez, Angel | G10: 1 | H10: 2.3541667 | I10: 2.3409722 | J10: 0.9627451 | K10: 0.99439528 | L10: =COUNTIF(F:F,F10) -> 1 | N10: =IF(H10<>"16:00:00",1,0) -> 1
A11: 40613 | B11: Dulce Pedraza | C11: Eder Garza | D11: 79437 | E11: TLGWM | F11: Garcia, Arif | G11: 1 | H11: 2.3125 | I11: 2.2993056 | J11: 0.9627451 | K11: 0.99429429 | L11: =COUNTIF(F:F,F11) -> 1 | N11: =IF(H11<>"16:00:00",1,0) -> 1
A12: 40612 | B12: Dulce Pedraza | C12: Eder Garza | D12: 76678342 | E12: TLGWM | F12: De La Garza, Pablo | G12: 1 | H12: 2.2708333 | I12: 2.2576389 | J12: 0.9627451 | K12: 0.9941896 | L12: =COUNTIF(F:F,F12) -> 1 | N12: =IF(H12<>"16:00:00",1,0) -> 1
A13: 40627 | B13: Gladys Lazaro | C13: Edgar Padilla | D13: 79327834 | E13: TLGM | F13: Mendizabal, Denise | G13: 1 | H13: 3.9375 | I13: 2.8826389 | J13: 0.9627451 | K13: 0.73209877 | L13: =COUNTIF(F:F,F13) -> 1 | N13: =IF(H13<>"16:00:00",1,0) -> 1
... A63: 40600 | B63: Jorge Bustos | C63: Cesar Hernandez | D63: 79253 | E63: UHVM | F63: Rangel, Santiago | G63: 1 | H63: 4.5625 | I63: 1.7576389 | J63: 0.9627451 | K63: 0.38523592 | L63: =COUNTIF(F:F,F63) -> 1 | N63: =IF(H63<>"16:00:00",1,0) -> 1
J64: 0.9
J65: 0.89
A66: Grafica - 30%
A67: Instrucciones: Aplicar las preguntas en la hoja correspondiente. | C67: Aplicar en Hoja | D67: Validacion
A68: 1 | B68: Generar una Tabla en base a la hoja "Base" la cual muestre los resultados de Adherencia a nivel supervisor, tomar en cuenta que no es un promedio de los resultados de adherencia por lo cual necesitan recalcularlo en base a la siguiente formula: %ADH = Conexion en adherencia / horas programadas | C68: Tabla Dinámica | D68: Se realiza grafica en hoja Base
A69: 2 | B69: Generar una Gráfica de Barras en base a la tabla generada con la pregunta anterior. | C69: Gráfica | D69: Se realiza grafica en hoja Base
A72: Etiquetas de fila | B72: Cuenta de Resultado Adherencia
A73: 0.99509044 | B73: 1
A74: 0.99501312 | B74: 1
A75: 0.99493333 | B75: 1
A76: 0.99485095 | B76: 1
A77: 0.99476584 | B77: 1
A78: 0.99467787 | B78: 1
A79: 0.99458689 | B79: 1
A80: 0.99449275 | B80: 1
A81: 0.99439528 | B81: 1
A82: 0.99429429 | B82: 1
A83: 0.9941896 | B83: 1
A84: 0.73209877 | B84: 1
... A132: 0.12493639 | B132: 1
A133: Total general | B133: 60
A135: Tabla Dinámica - 30%
A136: Instrucciones: Aplicar las preguntas en la hoja correspondiente. | C136: Aplicar en Hoja | D136: Validacion
A137: 1 | B137: Generar una Tabla Dinámica en base a la hoja "Base" la cual muestre los resultados de Adherencia a nivel Acm, Supervisor y Agente, tomar en cuenta que no es un promedio de los resultados de adherencia por lo cual necesitan insertar un campo calculado con la siguiente formula: %ADH = Conexion en adherencia/horas programadas | C137: Tabla Dinámica y grafica | D137: Se realiza grafica en hoja Base
A140: Cuenta de Resultado Adherencia
D141: 0.12493639 | E141: 0.13809524 | F141: 0.1508642 | G141: 0.16326034 | H141: 0.16945899 | I141: 0.17529976 | J141: 0.17806563 | K141: 0.18649573 | L141: 0.18699764 | M141: 0.19475465 | N141: 0.1983683 | O141: 0.20284757 | P141: 0.20942529 | Q141: 0.21077944 | R141: 0.21855501 | S141: 0.22617886 | T141: 0.23365539 | U141: 0.24098884 | V141: 0.24818325 | W141: 0.25524257 | X141: 0.26217054 | Y141: 0.26897081 | Z141: 0.38523592 | AA141: 0.3907994 | AB141: 0.39626308 | AC141: 0.40162963 | AD141: 0.40690162 | AE141: 0.4106576 | AF141: 0.41208151 | AG141: 0.41856823 | AH141: 0.42626932 | AI141: 0.43376906 | AJ141: 0.44107527 | AK141: 0.44819533 | AL141: 0.45513627 | AM141: 0.46046176 | AN141: 0.46190476 | AO141: 0.46850716 | AP141: 0.47494949 | AQ141: 0.48123752 | AR141: 0.48737673 | AS141: 0.56354776 | AT141: 0.56859345 | AU141: 0.57352381 | AV141: 0.57834275 | AW141: 0.583054 | AX141: 0.72025783 | AY141: 0.72331512 | AZ141: 0.72630631 | BA141: 0.72923351 | BB141: 0.73209877 | BC141: 0.9941896 | BD141: 0.99429429 | BE141: 0.99439528 | BF141: 0.99449275 | BG141: 0.99458689 | BH141: 0.99467787 | BI141: 0.99476584 | BJ141: 0.99485095 | BK141: 0.99493333 | BL141: 0.99501312 | BM141: 0.99509044 | BN141: Total general
...

Sheet Sheet1
